Workbook

Sheet Read Me

Sheet Dashboard
C13: SELECTIONS | E13: INPUTS | J13: OUTPUTS
F14: Value | G14: Coefficients | H14: Weighted Value
C15: GDP Tier and PPP | E15: X | J15: X - the predicted natural log of the median | K15: =SUM(H16:H27) -> 2.3501879
C16: Tier 1 (GDP available), 2021 PPPs | E16: Intercept | F16: 1 | G16: =_xlfn.XLOOKUP($C$16,'Estimated Coefficients'!$B$2:$E$2,'Estimated Coefficients'!$B4:$E4) -> -2.2640446 | H16: =F16*G16 -> -2.2640446 | J16: Z - the predicted Gini coefficient | K16: =SUM(H29:H32) -> 0.34648927
E17: Natural Log GDP per capita | F17: =LN(12276) -> 9.4154014 | G17: =_xlfn.XLOOKUP($C$16,'Estimated Coefficients'!$B$2:$E$2,'Estimated Coefficients'!$B5:$E5) -> 0.43163307 | H17: =F17*G17 -> 4.0639986 | J17: Poverty Rate | K17: =(1+(EXP(K15)/C19)^(1/K16))^-1 -> 0.33734452
C18: Poverty Line (2017/2021 PPP per day) | E18: Natural Log under-5 mortality | F18: =LN(14.8) -> 2.6946272 | G18: =_xlfn.XLOOKUP($C$16,'Estimated Coefficients'!$B$2:$E$2,'Estimated Coefficients'!$B6:$E6) -> -0.15322289 | H18: =F18*G18 -> -0.41287856
C19: 8.3 | E19: Life expectancy (year) | F19: 71.1 | G19: =_xlfn.XLOOKUP($C$16,'Estimated Coefficients'!$B$2:$E$2,'Estimated Coefficients'!$B7:$E7) -> 0.014232587 | H19: =F19*G19 -> 1.0119369
E20: Rural population share (%) | F20: 18.1 | G20: =_xlfn.XLOOKUP($C$16,'Estimated Coefficients'!$B$2:$E$2,'Estimated Coefficients'!$B8:$E8) -> -0.002697485 | H20: =F20*G20 -> -0.048824479
C21: Income Group | E21: Income group
C22: Low income | E22: Low income | F22: =IF(E22=$C$22,1) -> 1 | G22: =_xlfn.XLOOKUP($C$16,'Estimated Coefficients'!$B$2:$E$2,'Estimated Coefficients'!$B10:$E10) -> 0 | H22: =F22*G22 -> 0
E23: Lower-middle income | F23: =IF(E23=$C$22,1) -> FALSE | G23: =_xlfn.XLOOKUP($C$16,'Estimated Coefficients'!$B$2:$E$2,'Estimated Coefficients'!$B11:$E11) -> 0 | H23: =F23*G23 -> 0
C24: Regional Group | E24: Upper-middle income | F24: =IF(E24=$C$22,1) -> FALSE | G24: =_xlfn.XLOOKUP($C$16,'Estimated Coefficients'!$B$2:$E$2,'Estimated Coefficients'!$B12:$E12) -> 0 | H24: =F24*G24 -> 0
C25: Middle East & North America | E25: High income | F25: =IF(E25=$C$22,1) -> FALSE | G25: =_xlfn.XLOOKUP($C$16,'Estimated Coefficients'!$B$2:$E$2,'Estimated Coefficients'!$B13:$E13) -> 0 | H25: =F25*G25 -> 0
E26: Welfare type (income=1) | F26: =IF(C28="Income", 1,0) -> 0 | G26: =_xlfn.XLOOKUP($C$16,'Estimated Coefficients'!$B$2:$E$2,'Estimated Coefficients'!$B14:$E14) -> -4.1401951 | H26: =F26*G26 -> 0
C27: Welfare Type | E27: Welfare type * ln GDP pc | F27: =F26*F17 -> 0 | G27: =_xlfn.XLOOKUP($C$16,'Estimated Coefficients'!$B$2:$E$2,'Estimated Coefficients'!$B15:$E15) -> 0.43278085 | H27: =F27*G27 -> 0
C28: Consumption | E28: Z
E29: Intercept | F29: 1 | G29: =_xlfn.XLOOKUP($C$16,'Estimated Coefficients'!$B$2:$E$2,'Estimated Coefficients'!$B17:$E17) -> 0.34648927 | H29: =F29*G29 -> 0.34648927
E30: Europe & Central Asia | F30: =IF(E30=$C$25,1,0) -> 0 | G30: =_xlfn.XLOOKUP($C$16,'Estimated Coefficients'!$B$2:$E$2,'Estimated Coefficients'!$B18:$E18) -> -0.026387236 | H30: =F30*G30 -> 0
E31: Latin America & Caribbean | F31: =IF(E31=$C$25,1,0) -> 0 | G31: =_xlfn.XLOOKUP($C$16,'Estimated Coefficients'!$B$2:$E$2,'Estimated Coefficients'!$B19:$E19) -> 0.14816256 | H31: =F31*G31 -> 0
E32: Sub-Saharan Africa | F32: =IF(E32=$C$25,1,0) -> 0 | G32: =_xlfn.XLOOKUP($C$16,'Estimated Coefficients'!$B$2:$E$2,'Estimated Coefficients'!$B20:$E20) -> 0.060945453 | H32: =F32*G32 -> 0

Sheet Input_Data
A1: year | B1: country code | C1: Europe & Central Asia | D1: Latin America & Caribbean | E1: Sub-Saharan Africa | F1: Lower-middle income | G1: Upper-middle income | H1: High income | I1: Welfare Type: Income = 1 | J1: Natural Log GDP per capita (2021 PPP) | K1: Natural Log GDP per capita (2017 PPP) | L1: Rural population share (%) | M1: Life expectancy (year) | N1: Natural Log under-5 mortality
A2: 1981 | B2: ABW | C2: 0 | D2: 1 | E2: 0 | F2: 0 | G2: 0 | H2: 1 | I2: 1 | L2: 49.544 | M2: 71.344 | N2: 25.796
A3: 1981 | B3: AFG | C3: 0 | D3: 0 | E3: 0 | F3: 0 | G3: 0 | H3: 0 | I3: 0 | L3: 83.438 | M3: 39.406 | N3: 257.098
A4: 1981 | B4: AGO | C4: 0 | D4: 0 | E4: 1 | F4: 1 | G4: 0 | H4: 0 | I4: 0 | J4: 8218.2725 | K4: 6355.6076 | L4: 74.563 | M4: 42.556 | N4: 241.034
A5: 1981 | B5: ALB | C5: 1 | D5: 0 | E5: 0 | F5: 1 | G5: 0 | H5: 0 | I5: 0 | J5: 5351.0464 | K5: 4847.8026 | L5: 65.976 | M5: 70.145 | N5: 58.19
A6: 1981 | B6: AND | C6: 1 | D6: 0 | E6: 0 | F6: 0 | G6: 0 | H6: 1 | I6: 1 | J6: 52953.373 | K6: 44450.313 | L6: 7.2 | M6: 77.391 | N6: 13.086
A7: 1981 | B7: ARE | C7: 0 | D7: 0 | E7: 0 | F7: 0 | G7: 0 | H7: 1 | I7: 1 | J7: 212308.22 | K7: 209753.87 | L7: 19.317 | M7: 68.622 | N7: 32.265
A8: 1981 | B8: ARG | C8: 0 | D8: 1 | E8: 0 | F8: 0 | G8: 1 | H8: 0 | I8: 0 | J8: 20693.303 | K8: 17078.386 | L8: 16.687 | M8: 68.858 | N8: 39.655
A9: 1981 | B9: ARM | C9: 1 | D9: 0 | E9: 0 | F9: 1 | G9: 0 | H9: 0 | I9: 0 | L9: 33.741 | M9: 65.707 | N9: 70.54
A10: 1981 | B10: ASM | C10: 0 | D10: 0 | E10: 0 | F10: 0 | G10: 0 | H10: 1 | I10: 1 | L10: 24.957 | M10: 69.731 | N10: 20.495
A11: 1981 | B11: ATG | C11: 0 | D11: 1 | E11: 0 | F11: 0 | G11: 1 | H11: 0 | I11: 0 | J11: 12124.147 | K11: 9548.9394 | L11: 65.302 | M11: 73.32 | N11: 15.147
A12: 1981 | B12: AUS | C12: 0 | D12: 0 | E12: 0 | F12: 0 | G12: 0 | H12: 1 | I12: 1 | J12: 30186.63 | K12: 26146.197 | L12: 14.3 | M12: 74.783 | N12: 12.637
A13: 1981 | B13: AUT | C13: 1 | D13: 0 | E13: 0 | F13: 0 | G13: 0 | H13: 1 | I13: 1 | J13: 37303.843 | K13: 31788.676 | L13: 34.636 | M13: 72.99 | N13: 14.98
A14: 1981 | B14: AZE | C14: 1 | D14: 0 | E14: 0 | F14: 1 | G14: 0 | H14: 0 | I14: 0 | L14: 47.103 | M14: 61.908 | N14: 110.79
A15: 1981 | B15: BDI | C15: 0 | D15: 0 | E15: 1 | F15: 0 | G15: 0 | H15: 0 | I15: 0 | J15: 1166.1398 | K15: 1007.6652 | L15: 95.497 | M15: 46.412 | N15: 211.38
A16: 1981 | B16: BEL | C16: 1 | D16: 0 | E16: 0 | F16: 0 | G16: 0 | H16: 1 | I16: 1 | J16: 35492.13 | K16: 29867.217 | L16: 4.465 | M16: 73.652 | N16: 13.741
A17: 1981 | B17: BEN | C17: 0 | D17: 0 | E17: 1 | F17: 0 | G17: 0 | H17: 0 | I17: 0 | J17: 2282.6973 | K17: 2165.7133 | L17: 71.99 | M17: 48.122 | N17: 208.054
A18: 1981 | B18: BFA | C18: 0 | D18: 0 | E18: 1 | F18: 0 | G18: 0 | H18: 0 | I18: 0 | J18: 1000.3783 | K18: 915.28317 | L18: 90.572 | M18: 46.866 | N18: 235.973
A19: 1981 | B19: BGD | C19: 0 | D19: 0 | E19: 0 | F19: 0 | G19: 0 | H19: 0 | I19: 0 | J19: 1864.1241 | K19: 1515.5228 | L19: 84.199 | M19: 52.638 | N19: 199.597
A20: 1981 | B20: BGR | C20: 1 | D20: 0 | E20: 0 | F20: 1 | G20: 0 | H20: 0 | I20: 0 | J20: 10716.679 | K20: 8892.6947 | L20: 37.397 | M20: 71.478 | N20: 22.857
A21: 1981 | B21: BHR | C21: 0 | D21: 0 | E21: 0 | F21: 0 | G21: 0 | H21: 1 | I21: 1 | J21: 51912.87 | K21: 48370.453 | L21: 13.683 | M21: 71.037 | N21: 30.977
A22: 1981 | B22: BHS | C22: 0 | D22: 1 | E22: 0 | F22: 0 | G22: 0 | H22: 1 | I22: 1 | J22: 29490.689 | K22: 30590.279 | L22: 26.157 | M22: 69.368 | N22: 32.015
A23: 1981 | B23: BIH | C23: 1 | D23: 0 | E23: 0 | F23: 0 | G23: 1 | H23: 0 | I23: 0 | L23: 63.718 | M23: 70.055 | N23: 31.85
A24: 1981 | B24: BLR | C24: 1 | D24: 0 | E24: 0 | F24: 0 | G24: 1 | H24: 0 | I24: 0 | L24: 42.416 | M24: 70.754 | N24: 19.775
A25: 1981 | B25: BLZ | C25: 0 | D25: 1 | E25: 0 | F25: 1 | G25: 0 | H25: 0 | I25: 0 | J25: 6959.6741 | K25: 5484.8717 | L25: 50.817 | M25: 67.095 | N25: 62.228
A26: 1981 | B26: BMU | C26: 0 | D26: 0 | E26: 0 | F26: 0 | G26: 0 | H26: 1 | I26: 1 | J26: 77235.608 | K26: 68621.051 | L26: 0 | M26: 72.892 | N26: 17.205
A27: 1981 | B27: BOL | C27: 0 | D27: 1 | E27: 0 | F27: 1 | G27: 0 | H27: 0 | I27: 0 | J27: 6424.0751 | K27: 5669.5689 | L27: 53.541 | M27: 52.259 | N27: 201.04
A28: 1981 | B28: BRA | C28: 0 | D28: 1 | E28: 0 | F28: 0 | G28: 1 | H28: 0 | I28: 0 | J28: 12620.97 | K28: 10366.98 | L28: 33.63 | M28: 62.267 | N28: 91.491
A29: 1981 | B29: BRB | C29: 0 | D29: 1 | E29: 0 | F29: 0 | G29: 1 | H29: 0 | I29: 0 | J29: 15342.781 | K29: 14653.884 | L29: 60.172 | M29: 72.63 | N29: 25.817
A30: 1981 | B30: BRN | C30: 0 | D30: 0 | E30: 0 | F30: 0 | G30: 0 | H30: 1 | I30: 1 | J30: 210011.31 | K30: 163977.77 | L30: 34.901 | M30: 69.344 | N30: 20.113
A31: 1981 | B31: BTN | C31: 0 | D31: 0 | E31: 0 | F31: 0 | G31: 0 | H31: 0 | I31: 0 | J31: 1952.1625 | K31: 1690.8196 | L31: 89.354 | M31: 48.975 | N31: 187.475
A32: 1981 | B32: BWA | C32: 0 | D32: 0 | E32: 1 | F32: 1 | G32: 0 | H32: 0 | I32: 0 | J32: 5419.0837 | K32: 4903.1134 | L32: 82.448 | M32: 63.027 | N32: 68.666
A33: 1981 | B33: CAF | C33: 0 | D33: 0 | E33: 1 | F33: 0 | G33: 0 | H33: 0 | I33: 0 | J33: 1486.3275 | K33: 1190.0286 | L33: 65.798 | M33: 50.028 | N33: 186.181
A34: 1981 | B34: CAN | C34: 0 | D34: 0 | E34: 0 | F34: 0 | G34: 0 | H34: 1 | I34: 1 | J34: 34781.288 | K34: 30107.259 | L34: 24.288 | M34: 75.482 | N34: 11.684
A35: 1981 | B35: CHE | C35: 1 | D35: 0 | E35: 0 | F35: 0 | G35: 0 | H35: 1 | I35: 1 | J35: 55982.187 | K35: 48702.65 | L35: 25.534 | M35: 75.818 | N35: 9.731
A36: 1981 | B36: CHI | C36: 1 | D36: 0 | E36: 0 | F36: 0 | G36: 0 | H36: 1 | I36: 1 | L36: 68.091 | M36: 73.78165 | N36: 22.811602
A37: 1981 | B37: CHL | C37: 0 | D37: 1 | E37: 0 | F37: 1 | G37: 0 | H37: 0 | I37: 0 | J37: 9745.3783 | K37: 8489.0231 | L37: 18.222 | M37: 69.822 | N37: 31.889
A38: 1981 | B38: CHN | C38: 0 | D38: 0 | E38: 0 | F38: 0 | G38: 0 | H38: 0 | I38: 0 | J38: 812.666 | K38: 728.50245 | L38: 79.882 | M38: 64.778 | N38: 61.63
A39: 1981 | B39: CIV | C39: 0 | D39: 0 | E39: 1 | F39: 1 | G39: 0 | H39: 0 | I39: 0 | J39: 6901.1722 | K39: 5825.6057 | L39: 62.956 | M39: 51.791 | N39: 165.814
A40: 1981 | B40: CMR | C40: 0 | D40: 0 | E40: 1 | F40: 1 | G40: 0 | H40: 0 | I40: 0 | J40: 3980.205 | K40: 3125.307 | L40: 67.239 | M40: 51.227 | N40: 171.85
...

Sheet Estimated Coefficients
A1: PPP | B1: 2021 PPPs | C1: 2021 PPPs | D1: 2017 PPPs | E1: 2017 PPPs
A2: Tier | B2: Tier 1 (GDP available), 2021 PPPs | C2: Tier 2 (GDP unavailable), 2021 PPPs | D2: Tier 1 (GDP available), 2017 PPPs | E2: Tier 2 (GDP unavailable), 2017 PPPs
A3: X
A4: Intercept | B4: -2.2640446 | C4: 1.604646 | D4: -2.5147202 | E4: 1.4188586
A5: Log GDP per capita | B5: 0.43163307 | C5: 0 | D5: 0.49154653 | E5: 0
A6: Log under-5 mortality | B6: -0.15322289 | C6: -0.2565658 | D6: -0.16449754 | E6: -0.23232238
A7: Life expectancy | B7: 0.014232587 | C7: 0.019700353 | D7: 0.009014481 | E7: 0.018963891
A8: Rural population share | B8: -0.002697485 | C8: -0.007744599 | D8: -0.001307895 | E8: -0.00776163
A9: Income group | B9: 0 | C9: 0 | D9: 0 | E9: 0
A10: Low income | B10: 0 | C10: 0 | D10: 0 | E10: 0
A11: Lower-middle income | B11: 0 | C11: 0.22192086 | D11: 0 | E11: 0.20903477
A12: Upper-middle income | B12: 0 | C12: 0.44856047 | D12: 0 | E12: 0.55203232
A13: High income | B13: 0 | C13: 1.1388756 | D13: 0 | E13: 1.2483051
A14: Welfare type (income=1) | B14: -4.1401951 | C14: 0 | D14: -4.4971338 | E14: 0
A15: Welfare type * log GDP pc | B15: 0.43278085 | C15: 0 | D15: 0.47075135 | E15: 0
... A20: Sub-Saharan Africa | B20: 0.060945453 | C20: 0.066503355 | D20: 0.024563342 | E20: 0.068309194

Sheet Selection List 
A1: Tier Selection
A2: Tier 1 (GDP available), 2021 PPPs
A3: Tier 2 (GDP unavailable), 2021 PPPs
A4: Tier 1 (GDP available), 2017 PPPs
A5: Tier 2 (GDP unavailable), 2017 PPPs
A7: Poverty Line Selection (2021 PPP per day)
A8: 3
A9: 4.2
A10: 8.3
A11: 2.15
A12: 3.65
A13: 6.85
A15: Income Group
A16: Low income
A17: Lower-middle income
A18: Upper-middle income
A19: High income
A21: Regional Group
A22: Europe & Central Asia
A23: Latin America & Caribbean
A24: Sub-Saharan Africa
A25: Middle East & North America
A26: East Asia & Pacific
A27: South Asia
... A32: Income
